<?xml version="1.0"?>
<robot name="double_pendulum" xmlns:xacro="http://www.ros.org/wiki/xacro">
  <!-- World link -->
  <link name="world"/>
  
  <!-- Link base (fijo) -->
  <link name="base_link">
      <inertial>
          <origin xyz="0 0 0"/>
          <mass value="1.5"/>
          <inertia ixx="0.01" ixy="0.0" ixz="0.0" iyy="0.01" iyz="0.0" izz="0.001"/>
      </inertial>
      <visual>
          <origin xyz="0 0 0"/>
          <geometry>
              <cylinder radius="0.05" length="0.04"/>
          </geometry>
          <material name="gray">
              <color rgba="0.5 0.5 0.5 1"/>
          </material>
      </visual>
      <collision>
          <origin xyz="0 0 0"/>
          <geometry>
              <cylinder radius="0.05" length="0.02"/>
          </geometry>
      </collision>
  </link>
  
  <!-- Primer eslabón -->
  <link name="link1">
      <inertial>
          <origin xyz="0.1 0 0"/>
          <mass value="1.5"/>
          <inertia ixx="0.01" ixy="0.0" ixz="0.0" iyy="0.01" iyz="0.0" izz="0.001"/>
      </inertial>
      <visual>
          <origin xyz="0.1 0 0"/>
          <geometry>
              <box size="0.22 0.02 0.02"/>
          </geometry>
          <material name="blue">
              <color rgba="0 0 1 1"/>
          </material>
      </visual>
      <collision>
          <origin xyz="0.1 0 0"/>
          <geometry>
              <box size="0.2 0.02 0.02"/>
          </geometry>
      </collision>
  </link>

  <!-- Segundo eslabón -->
  <link name="link2">
      <inertial>
          <origin xyz="0.1 0 0"/>
          <mass value="1.0"/>
          <inertia ixx="0.01" ixy="0.0" ixz="0.0" iyy="0.01" iyz="0.0" izz="0.0001"/>
      </inertial>
      <visual>
          <origin xyz="0.1 0 0"/>
          <geometry>
              <box size="0.22 0.02 0.02"/>
          </geometry>
          <material name="red">
              <color rgba="1 0 0 1"/>
          </material>
      </visual>
      <collision>
          <origin xyz="0.1 0 0"/>
          <geometry>
              <box size="0.2 0.02 0.02"/>
          </geometry>
      </collision>
  </link>
  
  <!--******************* DEFINICIONES DE JUNTAS  *******************-->
  <!-- Junta fija entre world y base_link -->
  <joint name="fixed" type="fixed">
      <parent link="world"/>
      <child link="base_link"/>
      <origin xyz="0 0 0.02" rpy="0 0 0"/>
  </joint>
  
  <!-- Junta entre base y link1 -->
  <joint name="joint1" type="revolute">
      <parent link="base_link"/>
      <child link="link1"/>
      <origin xyz="0 0 0.03"/>
      <axis xyz="0 0 1"/>
      <limit effort="1000" lower="-3.14" upper="3.14" velocity="5"/>
      <dynamics damping="0.1" friction="0.01"/>
  </joint>
  
  <!-- Junta entre link1 y link2 -->
  <joint name="joint2" type="revolute">
      <parent link="link1"/>
      <child link="link2"/>
      <origin xyz="0.2 0 0.02"/>
      <axis xyz="0 0 1"/>
      <limit effort="1000" lower="-3.14" upper="3.14" velocity="5"/>
      <dynamics damping="0.1" friction="0.01"/>
  </joint>



  <ros2_control name="GazeboSystem" type="system">
    <hardware>
      <plugin>gz_ros2_control/GazeboSimSystem</plugin>
    </hardware>
    <joint name="joint1">
      <command_interface name="position">
        <param name="min">-3.14</param>
        <param name="max">3.14</param>
      </command_interface>    
      <command_interface name="effort">
        <param name="min">-1000</param>
        <param name="max">1000</param>
      </command_interface>
      <state_interface name="position">
        <param name="initial_value">1.0</param>
      </state_interface>
      <state_interface name="velocity"/>
      <state_interface name="effort"/>
    </joint>

    <joint name="joint2">
      <command_interface name="position">
        <param name="min">-3.14</param>
        <param name="max">3.14</param>
      </command_interface>    
      <command_interface name="effort">
        <param name="min">-1000</param>
        <param name="max">1000</param>
      </command_interface>
      <state_interface name="position">
        <param name="initial_value">1.0</param>
      </state_interface>
      <state_interface name="velocity"/>
      <state_interface name="effort"/>
    </joint>
  </ros2_control>

  <!-- ros_control plugin -->
  <gazebo>
    <plugin filename="gz_ros2_control-system" name="gz_ros2_control::GazeboSimROS2ControlPlugin">
      <parameters>/root/ros2_ws/install/clase3/share/clase3/config/ros2_controllers.yaml</parameters>
      <robot_param>robot_description</robot_param>
      <robot_param_node>robot_state_publisher</robot_param_node>
    </plugin>
  </gazebo>
</robot>

